<?xml version="1.0" encoding="utf-8" ?>
<!-- This URDF was automatically created by SolidWorks to URDF Exporter! Originally created by Stephen Brawner (brawner@gmail.com) 
     Commit Version: 1.5.1-0-g916b5db  Build Version: 1.5.7152.31018
     For more information, please see http://wiki.ros.org/sw_urdf_exporter -->
<robot name="kuka10">
    <material name="DarkGrey">
        <color rgba="0.3 0.3 0.3 1.0" />
    </material>
    <material name="Red">
        <color rgba="0.3 0.3 0.3 1.0" />
    </material>
    <material name="Black">
        <color rgba="0 0 0 1.0" />
    </material>
    <material name="Orange">
        <color rgba="1.0 0.487 0 1.0" />
    </material>
    <material name="Silver">
        <color rgba="1.0 1.0 1.0 1.0" />
    </material>
    <material name="Grey">
        <color rgba="0.7 0.7 0.7 1.0" />
    </material>
    <material name="Blue">
        <color rgba="0.0 0.0 0.8 1.0" />
    </material>
    <material name="HandGray">
        <color rgba="0.953 0.996 0.694 1.0" />
    </material>
    <material name="SickBlue">
        <color rgba="0.3058 0.5921 0.7294 1.0" />
    </material>
    <link name="base">
        <visual>
            <origin xyz="0 0 0" rpy="0 0 0" />
            <geometry>
                <mesh filename="/home/sathak/Desktop/ros2_lwr/src/kuka10/meshes/base.STL" />
            </geometry>
            <material name="Orange" />
        </visual>
        <collision>
            <origin xyz="0 0 0" rpy="0 0 0" />
            <geometry>
                <mesh filename="/home/sathak/Desktop/ros2_lwr/src/kuka10/meshes/base.STL" />
            </geometry>
        </collision>
    </link>
    <link name="link0">
        
<inertial>
            <origin xyz="-0.01839 -3.5933E-07 0.11546" rpy="0 0 0" />
            <mass value="26.274" />
            <inertia ixx="0.18457" ixy="3.5048E-05" ixz="-0.0010764" iyy="0.22337" iyz="7.5521E-07" izz="0.19181" />
        </inertial>

        <visual>
            <origin xyz="0 0 0" rpy="0 0 0" />
            <geometry>
                <mesh filename="package://kuka10/meshes/link0.STL" />
            </geometry>
            <material name="Orange" />
        </visual>
        <collision>
            <origin xyz="0 0 0" rpy="0 0 0" />
            <geometry>
                <mesh filename="package://kuka10/meshes/link0.STL" />
            </geometry>
        </collision>
    </link>
    <joint name="joint0" type="fixed">
        <origin xyz="0 0 0.1" rpy="0 0 0" />
        <parent link="base" />
        <child link="link0" />
        <axis xyz="0 0 0" />
    </joint>
    <link name="link1">
        
<inertial>
            <origin xyz="0.0079083 -0.00051127 0.11392" rpy="0 0 0" />
            <mass value="16.138" />
            <inertia ixx="0.19309" ixy="0.0006758" ixz="-0.013379" iyy="0.12335" iyz="0.0013217" izz="0.14549" />
        </inertial>

        <visual>
            <origin xyz="0 0 0" rpy="0 0 0" />
            <geometry>
                <mesh filename="package://kuka10/meshes/link1.STL" />
            </geometry>
            <material name="Orange" />
        </visual>
        <collision>
            <origin xyz="0 0 0" rpy="0 0 0" />
            <geometry>
                <mesh filename="package://kuka10/meshes/link1.STL" />
            </geometry>
        </collision>
    </link>
    <joint name="joint1" type="continuous">
        <origin xyz="0 0 0.2197" rpy="0 0 -0.7749" />
        <parent link="link0" />
        <child link="link1" />
        <axis xyz="0 0 1" />
    </joint>
    <link name="link2">
        
<inertial>
            <origin xyz="-0.00911156381912787 0.00127180641469707 0.26714923517814" rpy="0 0 0" />
            <mass value="29.2099116534424" />
            <inertia ixx="1.34821566118044" ixy="-0.000330024096012352" ixz="0.00439133420283591" iyy="1.27460889813477" iyz="-0.00958269944703305" izz="0.148351469990613" />
        </inertial>

        <visual>
            <origin xyz="0 0 0" rpy="0 0 0" />
            <geometry>
                <mesh filename="package://kuka10/meshes/link2.STL" />
            </geometry>
            <material name="Orange" />
        </visual>
        <collision>
            <origin xyz="0 0 0" rpy="0 0 0" />
            <geometry>
                <mesh filename="package://kuka10/meshes/link2.STL" />
            </geometry>
        </collision>
    </link>
    <joint name="joint2" type="continuous">
        <origin xyz="0.025 0 0.1803" rpy="0 0.1845 0" />
        <parent link="link1" />
        <child link="link2" />
        <axis xyz="0 1 0" />
    </joint>
    <link name="link3">
        
<inertial>
            <origin xyz="0.0524771518075861 -0.0027427841766853 0.0111313624197632" rpy="0 0 0" />
            <mass value="10.7356515464227" />
            <inertia ixx="0.0279341038364137" ixy="-0.00115290740250484" ixz="-0.00842464631152634" iyy="0.0773897506639313" iyz="-0.000157169490025021" izz="0.0746591519039725" />
        </inertial>

        <visual>
            <origin xyz="0 0 0" rpy="0 0 0" />
            <geometry>
                <mesh filename="package://kuka10/meshes/link3.STL" />
            </geometry>
            <material name="Orange" />
        </visual>
        <collision>
            <origin xyz="0 0 0" rpy="0 0 0" />
            <geometry>
                <mesh filename="package://kuka10/meshes/link3.STL" />
            </geometry>
        </collision>
    </link>
    <joint name="joint3" type="continuous">
        <origin xyz="0 0 0.56" rpy="3.1416 -0.9676 3.1416" />
        <parent link="link2" />
        <child link="link3" />
        <axis xyz="0 1 0" />
    </joint>
    <link name="link4">
        
<inertial>
            <origin xyz="0.165034583770522 0.00167296880256596 -6.4005807734191E-05" rpy="0 0 0" />
            <mass value="9.46899709406203" />
            <inertia ixx="0.0230437737584603" ixy="-0.00261444143202852" ixz="9.41523238675817E-05" iyy="0.0774068681899215" iyz="9.8811156792329E-06" izz="0.085272485874058" />
        </inertial>

        <visual>
            <origin xyz="0 0 0" rpy="0 0 0" />
            <geometry>
                <mesh filename="package://kuka10/meshes/link4.STL" />
            </geometry>
            <material name="Orange" />
        </visual>
        <collision>
            <origin xyz="0 0 0" rpy="0 0 0" />
            <geometry>
                <mesh filename="package://kuka10/meshes/link4.STL" />
            </geometry>
        </collision>
    </link>
    <joint name="joint4" type="continuous">
        <origin xyz="0.19382 0 0.025" rpy="1.0672 0 0" />
        <parent link="link3" />
        <child link="link4" />
        <axis xyz="1 0 0" />
    </joint>
    <link name="link5">
        
<inertial>
            <origin xyz="0.0114533423498129 -0.00142267053746903 -4.008378570175E-06" rpy="0 0 0" />
            <mass value="2.0616109473854" />
            <inertia ixx="0.00231059733509885" ixy="-2.67355053683567E-05" ixz="2.43063715679791E-07" iyy="0.00296181700973428" iyz="3.00991587522657E-07" izz="0.00337904061501" />
        </inertial>

        <visual>
            <origin xyz="0 0 0" rpy="0 0 0" />
            <geometry>
                <mesh filename="package://kuka10/meshes/link5.STL" />
            </geometry>
            <material name="Orange" />
        </visual>
        <collision>
            <origin xyz="0 0 0" rpy="0 0 0" />
            <geometry>
                <mesh filename="package://kuka10/meshes/link5.STL" />
            </geometry>
        </collision>
    </link>
    <joint name="joint5" type="continuous">
        <origin xyz="0.32118 0 0" rpy="-3.1416 -0.53505 3.1416" />
        <parent link="link4" />
        <child link="link5" />
        <axis xyz="0 1 0" />
    </joint>
    <link name="link6">
        
<inertial>
            <origin xyz="0.0661274920087269 2.4757973449141E-13 9.01350287337011E-06" rpy="0 0 0" />
            <mass value="0.205263387642513" />
            <inertia ixx="0.000146662065922685" ixy="-2.04558456761914E-16" ixz="-1.11524121828852E-08" iyy="7.82078474308265E-05" iyz="1.27135283163192E-15" izz="7.81985995901856E-05" />
        </inertial>

        <visual>
            <origin xyz="0 0 0" rpy="0 0 0" />
            <geometry>
                <mesh filename="package://kuka10/meshes/link6.STL" />
            </geometry>
            <material name="Orange" />
        </visual>
        <collision>
            <origin xyz="0 0 0" rpy="0 0 0" />
            <geometry>
                <mesh filename="package://kuka10/meshes/link6.STL" />
            </geometry>
        </collision>
    </link>
    <joint name="joint6" type="continuous">
        <origin xyz="0.011146 0 0" rpy="0.99552 0 0" />
        <parent link="link5" />
        <child link="link6" />
        <axis xyz="1 0 0" />
    </joint>
    
<transmission name="trans_joint1">
        <type>transmission_interface/SimpleTransmission</type>
        <joint name="joint1">
            <hardwareInterface>hardware_interface/EffortJointInterface</hardwareInterface>
        </joint>
        <actuator name="joint1_motor">
            <hardwareInterface>hardware_interface/EffortJointInterface</hardwareInterface>
            <mechanicalReduction>1</mechanicalReduction>
        </actuator>
    </transmission>
    <transmission name="trans_joint2">
        <type>transmission_interface/SimpleTransmission</type>
        <joint name="joint2">
            <hardwareInterface>hardware_interface/EffortJointInterface</hardwareInterface>
        </joint>
        <actuator name="joint2_motor">
            <hardwareInterface>hardware_interface/EffortJointInterface</hardwareInterface>
            <mechanicalReduction>1</mechanicalReduction>
        </actuator>
    </transmission>
    <transmission name="trans_joint3">
        <type>transmission_interface/SimpleTransmission</type>
        <joint name="joint3">
            <hardwareInterface>hardware_interface/EffortJointInterface</hardwareInterface>
        </joint>
        <actuator name="joint3_motor">
            <hardwareInterface>hardware_interface/EffortJointInterface</hardwareInterface>
            <mechanicalReduction>1</mechanicalReduction>
        </actuator>
    </transmission>
    <transmission name="trans_joint4">
        <type>transmission_interface/SimpleTransmission</type>
        <joint name="joint4">
            <hardwareInterface>hardware_interface/EffortJointInterface</hardwareInterface>
        </joint>
        <actuator name="joint4_motor">
            <hardwareInterface>hardware_interface/EffortJointInterface</hardwareInterface>
            <mechanicalReduction>1</mechanicalReduction>
        </actuator>
    </transmission>
    <transmission name="trans_joint5">
        <type>transmission_interface/SimpleTransmission</type>
        <joint name="joint5">
            <hardwareInterface>hardware_interface/EffortJointInterface</hardwareInterface>
        </joint>
        <actuator name="joint5_motor">
            <hardwareInterface>hardware_interface/EffortJointInterface</hardwareInterface>
            <mechanicalReduction>1</mechanicalReduction>
        </actuator>
    </transmission>
    <transmission name="trans_joint6">
        <type>transmission_interface/SimpleTransmission</type>
        <joint name="joint6">
            <hardwareInterface>hardware_interface/EffortJointInterface</hardwareInterface>
        </joint>
        <actuator name="joint6_motor">
            <hardwareInterface>hardware_interface/EffortJointInterface</hardwareInterface>
            <mechanicalReduction>1</mechanicalReduction>
        </actuator>
    </transmission>
    <gazebo>
        <plugin name="gazebo_ros_control" filename="libgazebo_ros_control.so">
            <robotNamespace>/</robotNamespace>
        </plugin>
    </gazebo>
</robot>
